<!DOCTYPE html>
<title>Canvas test: 2d.path.arcTo.negative</title>
<script src="../tests.js"></script>
<link rel="stylesheet" href="../tests.css">
<link rel="prev" href="2d.path.arcTo.shape.end.html" title="2d.path.arcTo.shape.end">
<link rel="next" href="2d.path.arcTo.zero.1.html" title="2d.path.arcTo.zero.1">
<body class="show_output">
<p>
 <a href="2d.path.arcTo.shape.end.html" accesskey="p" title="[p] 2d.path.arcTo.shape.end">&lt;</a>
 <a href="index.html">[index]</a>
 <a href="2d.path.arcTo.zero.1.html" accesskey="n" title="[n] 2d.path.arcTo.zero.1">&gt;</a>
<h1><a href="index.2d.html">2d</a>.<a href="index.2d.path.html">path</a>.<a href="index.2d.path.arcTo.html">arcTo</a>.negative</h1>
<p class="desc">arcTo() with negative radius throws an exception</p>
<div class="refs">References:
<ul>
<li><a href="spec.html#testrefs.2d.path.arcTo.negative">2d.path.arcTo.negative</a>

</ul>
</div>

<p class="output">Actual output:</p>
<canvas id="c" class="output" width="100" height="50"><p class="fallback">FAIL (fallback content)</p></canvas>

<ul id="d"></ul>
<script>
_addTest(function(canvas, ctx) {

try { var _thrown = false;
  ctx.arcTo(0, 0, 0, 0, -1);
} catch (e) { if (e.code != DOMException.INDEX_SIZE_ERR) _fail("Failed assertion: expected exception of type INDEX_SIZE_ERR, got: "+e.message); _thrown = true; } finally { _assert(_thrown, "should throw exception of type INDEX_SIZE_ERR: ctx.arcTo(0, 0, 0, 0, -1)"); }


});
</script>

